Workbook
Name CARBON_FRACTION_OM: '7. Settings'!$B$5
Name CO2E_FACTOR: '7. Settings'!$B$7
Name LORCA_MAX: '7. Settings'!$B$18
Name LORCA_MIN: '7. Settings'!$B$17
Name OM_FACTOR_IS_LOCAL: '7. Settings'!$B$6
Name PEATLAND_MIN_DEPTH_CM: '7. Settings'!$B$9
Name PLOT_AREA_M2: '7. Settings'!$B$10
Name QC_BD_MAX: '7. Settings'!$B$14
Name QC_BD_MIN: '7. Settings'!$B$13
Name QC_CARBON_PCT_MAX: '7. Settings'!$B$15
Name QC_RECOVERY_MIN: '7. Settings'!$B$16
Name REFERENCE_DEPTH_CM: '7. Settings'!$B$8
Name TARGET_CONFIDENCE: '7. Settings'!$B$12
Name TARGET_MARGIN: '7. Settings'!$B$11

Sheet 0. Instructions
A1: SIMULATED COMMUNITY SOIL CARBON EXAMPLE
B2: Western James Bay conceptual 350 km2 example; four simulated cores
A4: What this workbook does | B4: SIMULATED data only. Two wetland peat cores and two shallow forest soil profiles. Field date, positions, ecosystems and laboratory results are constructed. No vegetation stock or accumulation rate is supplied.
A6: COLOUR KEY
A7: Yellow | B7: TYPE HERE — field measurements you record.
A8: Blue | B8: TYPE HERE — lab results, once they come back.
A9: Grey | B9: Calculated for you. Do not type in grey cells.
A10: Green | B10: Summary output.
A11: Red | B11: A quality-control flag. Read it before trusting the row.
A13: ORDER OF WORK
A14: 1 | B14: Fill '1. Plot & Site Log' FIRST — one row per plot. Everything joins to it on Plot ID.
A15: 2 | B15: Fill '2. Core Log' — one row per core. Everything in the peat sheet joins to it on Core ID.
A16: 3 | B16: Fill '3. Peat Data' — one row per section, as the core is sectioned.
A17: 4 | B17: Add lab results (blue columns) to '3. Peat Data' when they return.
A18: 5 | B18: OPTIONAL: if the core has been dated, fill '4. Chronology' to get accumulation rates.
A19: 6 | B19: Read '5. Plot Summary' and '6. Site Summary'. Both calculate themselves.
A21: ⚠ IDs MUST MATCH | B21: Plot ID joins the Core Log to the Plot & Site Log; Core ID joins the Peat Data and the Chronology to the Core Log. A mismatch means that row's carbon never reaches the summary. Every sheet has a QC flags column that tells you when this happens.
A23: UNITS
A24: Depths | B24: centimetres (cm), measured down from the peat surface
A25: Bulk density | B25: g/cm³ — oven-dry mass ÷ sample volume (see the basis note on '3. Peat Data')
A26: Carbon content | B26: per cent of dry mass (%)
A27: Carbon stock | B27: kg C/m² at core, plot and site level; kg C for totals
A28: Accumulation rate | B28: g C/m²/yr — note the unit change: 1 kg C/m² per 1,000 yr = 1 g C/m²/yr
A29: Age | B29: years before the year the core was taken
A31: TWO STOCK NUMBERS, AND WHY
A32: Full profile | B32: Sampled profile: wetland peat to its constructed mineral contact; forest organic mat plus mineral soil to 45 or 60 cm. Deeper forest carbon is unknown.
A33: To reference depth | B33: Reference window is 0 to 100 cm below ground surface. Forest values cover only the sampled portion of that window and are not complete 1 m stocks.
A34: Why both | B34: Bansal et al. (2023) found 65% of wetland organic carbon sat between 30 and 120 cm. Report only a shallow fixed depth and you miss most of the store; report only full profiles and cores of different depths cannot be compared. So the workbook gives you both.
A36: WHAT'S BEYOND THE PRINTED GUIDE
A37: Uncertainty | B37: Four conceptual cores, one per plot/site. No site area is assigned and no valid AOI uncertainty interval is supplied.
A38: Eq 5 correction | B38: The guide's printed Eq 5 has its right-hand side in g/cm² and its left-hand side in kg/m². This workbook uses the correct form — summing the kg/m² core values — which is also what the guide's own example spreadsheet does.
A39: Carbon fraction | B39: Settable on '7. Settings', defaulting to the guide's 0.5. See 'R1. Reference' for why that is a convention rather than a constant.
A40: Accumulation rates | B40: The guide raises them in its introduction and its glossary but gives no method. '4. Chronology' supplies one — see Part 5 of the workshop.

Sheet 1. Plot & Site Log
A1: PLOT & SITE LOG
A2: SIMULATED locations and field metadata. K identifies Bog/Fen/Other using the original dropdown. Forest identity is in Vegetation zone and Notes. Plot area is a field footprint, not represented landscape area.
A4: Plot ID | B4: Site ID | C4: Study area | D4: Date | E4: Location | F4: Latitude | G4: Longitude | H4: GNSS accuracy (m) | I4: Datum | J4: Elevation (m) | K4: Wetland type | L4: Microform | M4: Vegetation zone | N4: Water table depth (cm) | O4: Plot area (m²) | P4: Notes
A5: PM-01 | B5: PM-01-A | F5: 56.098575 | G5: -87.67978 | I5: WGS84 | K5: Mudflat | O5: 100
A6: PM-02 | B6: PM-02-A | F6: 56.099636 | G6: -87.65064 | I6: WGS84 | K6: Bog | O6: 100
A7: PM-03 | B7: PM-03-A | F7: 56.110356 | G7: -87.67839 | I7: WGS84 | K7: Bog | O7: 100
A8: FS-01 | B8: FS-01 | F8: 55.965999 | G8: -87.6282 | I8: WGS84 | K8: other | O8: 100
A9: FS-02 | B9: FS-02 | F9: 55.992611 | G9: -87.62825 | I9: WGS84 | K9: other
A10: FS-03 | B10: FS-03 | F10: 56.128917 | G10: -87.87181 | I10: WGS84 | K10: other
A11: FS-04 | B11: FS-03 | F11: 56.074278 | G11: -87.79556 | I11: WGS84 | K11: other
A12: FS_05 | B12: FS_05 | F12: 56.079389 | G12: -87.75622 | I12: WGS84 | K12: other

Sheet 2. Core Log
A1: CORE LOG
A2: SIMULATED. Wetland depths are complete peat profiles. Forest profiles include a 4 or 6 cm organic mat plus shallow mineral soil; reaching the organic/mineral contact does not mean the whole soil profile was sampled.
A4: Core ID | B4: Plot ID | C4: Latitude | D4: Longitude | E4: Coring date | F4: Drives taken | G4: Bore depth (cm) | H4: Core length recovered (cm) | I4: Surface compaction (cm) | J4: Recovery ratio | K4: Depth to mineral contact (cm) | L4: Reached mineral contact? | M4: von Post at base | N4: Chamber length (cm) | O4: Chamber diameter (cm) | P4: Photo series? | Q4: Deepest section logged (cm) | R4: Stock over sampled profile (kg C/m²) | S4: Sampled stock in reference window (kg C/m²) | T4: Reaches reference depth? | U4: QC flags | V4: Notes
A5: PM-01-A | B5: PM-01-A | C5: 56.098575 | D5: -87.67978 | F5: 1 | G5: 14.5 | H5: 14.5 | I5: 0 | J5: =IF(OR($G5="",$H5="",$G5=0),"",$H5/$G5) -> 1 | K5: 1 | L5: Yes | P5: No | Q5: =IF($A5="","",IF(SUMPRODUCT(MAX((community_cores_FS!$B$5:$B$597=$A5)*community_cores_FS!$F$5:$F$597))=0,"",SUMPRODUCT(MAX((community_cores_FS!$B$5:$B$597=$A5)*community_cores_FS!$F$5:$F$597)))) -> 14.5 | R5: =IF($A5="","",IFERROR(SUMIFS(community_cores_FS!$P$5:$P$597,community_cores_FS!$B$5:$B$597,$A5),"")) -> 3.0578035 | S5: =IF($A5="","",IFERROR(SUMIFS(community_cores_FS!$Q$5:$Q$597,community_cores_FS!$B$5:$B$597,$A5),"")) -> 3.0578035 | T5: =IF(NOT(ISNUMBER($Q5)),"",IF($Q5>=REFERENCE_DEPTH_CM,"Yes","No")) -> No | V5: SIMULATED bog peat; contact at 220 cm; full organic profile sampled.
A6: PM-02-A | B6: PM-02-A | C6: 56.099636 | D6: -87.65064 | F6: 1 | G6: 20.7 | H6: 20.7 | I6: 0 | J6: =IF(OR($G6="",$H6="",$G6=0),"",$H6/$G6) -> 1 | K6: 20.7 | L6: Yes | P6: No | Q6: =IF($A6="","",IF(SUMPRODUCT(MAX((community_cores_FS!$B$5:$B$597=$A6)*community_cores_FS!$F$5:$F$597))=0,"",SUMPRODUCT(MAX((community_cores_FS!$B$5:$B$597=$A6)*community_cores_FS!$F$5:$F$597)))) -> 20.7 | R6: =IF($A6="","",IFERROR(SUMIFS(community_cores_FS!$P$5:$P$597,community_cores_FS!$B$5:$B$597,$A6),"")) -> 3.0833445 | S6: =IF($A6="","",IFERROR(SUMIFS(community_cores_FS!$Q$5:$Q$597,community_cores_FS!$B$5:$B$597,$A6),"")) -> 3.0833445 | T6: =IF(NOT(ISNUMBER($Q6)),"",IF($Q6>=REFERENCE_DEPTH_CM,"Yes","No")) -> No | V6: SIMULATED fen peat; contact at 160 cm; full organic profile sampled.
A7: PM-03-A | B7: PM-03-A | C7: 56.110356 | D7: -87.67839 | F7: 1 | G7: 30.725 | H7: 30.725 | I7: 0 | J7: =IF(OR($G7="",$H7="",$G7=0),"",$H7/$G7) -> 1 | K7: 30.375 | L7: Yes | P7: No | Q7: =IF($A7="","",IF(SUMPRODUCT(MAX((community_cores_FS!$B$5:$B$597=$A7)*community_cores_FS!$F$5:$F$597))=0,"",SUMPRODUCT(MAX((community_cores_FS!$B$5:$B$597=$A7)*community_cores_FS!$F$5:$F$597)))) -> 30.725 | R7: =IF($A7="","",IFERROR(SUMIFS(community_cores_FS!$P$5:$P$597,community_cores_FS!$B$5:$B$597,$A7),"")) -> 10.108268 | S7: =IF($A7="","",IFERROR(SUMIFS(community_cores_FS!$Q$5:$Q$597,community_cores_FS!$B$5:$B$597,$A7),"")) -> 10.108268 | T7: =IF(NOT(ISNUMBER($Q7)),"",IF($Q7>=REFERENCE_DEPTH_CM,"Yes","No")) -> No | V7: SIMULATED forest: 6 cm organic mat plus mineral soil sampled to 45 cm; deeper stock unknown.
A8: FS-01 | B8: FS-01 | C8: 55.965999 | D8: -87.6282 | F8: 1 | G8: 30 | H8: 30 | I8: 0 | J8: =IF(OR($G8="",$H8="",$G8=0),"",$H8/$G8) -> 1 | K8: 4 | L8: Yes | P8: No | Q8: =IF($A8="","",IF(SUMPRODUCT(MAX((community_cores_FS!$B$5:$B$597=$A8)*community_cores_FS!$F$5:$F$597))=0,"",SUMPRODUCT(MAX((community_cores_FS!$B$5:$B$597=$A8)*community_cores_FS!$F$5:$F$597)))) -> 30 | R8: =IF($A8="","",IFERROR(SUMIFS(community_cores_FS!$P$5:$P$597,community_cores_FS!$B$5:$B$597,$A8),"")) -> 14.263005 | S8: =IF($A8="","",IFERROR(SUMIFS(community_cores_FS!$Q$5:$Q$597,community_cores_FS!$B$5:$B$597,$A8),"")) -> 14.263005 | T8: =IF(NOT(ISNUMBER($Q8)),"",IF($Q8>=REFERENCE_DEPTH_CM,"Yes","No")) -> No | V8: SIMULATED forest: 4 cm organic mat plus mineral soil sampled to 60 cm; deeper stock unknown.
A9: FS-02 | B9: FS-02 | C9: 55.992611 | D9: -87.62825 | F9: 1 | G9: 30 | H9: 30 | J9: =IF(OR($G9="",$H9="",$G9=0),"",$H9/$G9) -> 1 | K9: 1 | L9: yes | P9: no | Q9: =IF($A9="","",IF(SUMPRODUCT(MAX((community_cores_FS!$B$5:$B$597=$A9)*community_cores_FS!$F$5:$F$597))=0,"",SUMPRODUCT(MAX((community_cores_FS!$B$5:$B$597=$A9)*community_cores_FS!$F$5:$F$597)))) -> 30 | R9: =IF($A9="","",IFERROR(SUMIFS(community_cores_FS!$P$5:$P$597,community_cores_FS!$B$5:$B$597,$A9),"")) -> 8.3815614 | S9: =IF($A9="","",IFERROR(SUMIFS(community_cores_FS!$Q$5:$Q$597,community_cores_FS!$B$5:$B$597,$A9),"")) -> 8.3815614 | T9: =IF(NOT(ISNUMBER($Q9)),"",IF($Q9>=REFERENCE_DEPTH_CM,"Yes","No")) -> No
A10: FS-03 | B10: FS-03 | C10: 56.128917 | D10: -87.87181 | F10: 1 | G10: 30 | H10: 30 | J10: =IF(OR($G10="",$H10="",$G10=0),"",$H10/$G10) -> 1 | K10: 1 | L10: yes | P10: no | Q10: =IF($A10="","",IF(SUMPRODUCT(MAX((community_cores_FS!$B$5:$B$597=$A10)*community_cores_FS!$F$5:$F$597))=0,"",SUMPRODUCT(MAX((community_cores_FS!$B$5:$B$597=$A10)*community_cores_FS!$F$5:$F$597)))) -> 30 | R10: =IF($A10="","",IFERROR(SUMIFS(community_cores_FS!$P$5:$P$597,community_cores_FS!$B$5:$B$597,$A10),"")) -> 4.2223031 | S10: =IF($A10="","",IFERROR(SUMIFS(community_cores_FS!$Q$5:$Q$597,community_cores_FS!$B$5:$B$597,$A10),"")) -> 4.2223031 | T10: =IF(NOT(ISNUMBER($Q10)),"",IF($Q10>=REFERENCE_DEPTH_CM,"Yes","No")) -> No
A11: FS-03 | B11: FS-03 | C11: 56.074278 | D11: -87.79556 | F11: 1 | G11: 30 | H11: 30 | J11: =IF(OR($G11="",$H11="",$G11=0),"",$H11/$G11) -> 1 | K11: 1 | L11: yes | P11: no | Q11: =IF($A11="","",IF(SUMPRODUCT(MAX((community_cores_FS!$B$5:$B$597=$A11)*community_cores_FS!$F$5:$F$597))=0,"",SUMPRODUCT(MAX((community_cores_FS!$B$5:$B$597=$A11)*community_cores_FS!$F$5:$F$597)))) -> 30 | R11: =IF($A11="","",IFERROR(SUMIFS(community_cores_FS!$P$5:$P$597,community_cores_FS!$B$5:$B$597,$A11),"")) -> 4.2223031 | S11: =IF($A11="","",IFERROR(SUMIFS(community_cores_FS!$Q$5:$Q$597,community_cores_FS!$B$5:$B$597,$A11),"")) -> 4.2223031 | T11: =IF(NOT(ISNUMBER($Q11)),"",IF($Q11>=REFERENCE_DEPTH_CM,"Yes","No")) -> No
A12: FS-05 | B12: FS-05 | C12: 56.079389 | D12: -87.75622 | F12: 1 | G12: 30 | H12: 30 | J12: =IF(OR($G12="",$H12="",$G12=0),"",$H12/$G12) -> 1 | K12: 1 | L12: yes | P12: no | Q12: =IF($A12="","",IF(SUMPRODUCT(MAX((community_cores_FS!$B$5:$B$597=$A12)*community_cores_FS!$F$5:$F$597))=0,"",SUMPRODUCT(MAX((community_cores_FS!$B$5:$B$597=$A12)*community_cores_FS!$F$5:$F$597)))) -> 30 | R12: =IF($A12="","",IFERROR(SUMIFS(community_cores_FS!$P$5:$P$597,community_cores_FS!$B$5:$B$597,$A12),"")) -> 6.1054498 | S12: =IF($A12="","",IFERROR(SUMIFS(community_cores_FS!$Q$5:$Q$597,community_cores_FS!$B$5:$B$597,$A12),"")) -> 6.1054498 | T12: =IF(NOT(ISNUMBER($Q12)),"",IF($Q12>=REFERENCE_DEPTH_CM,"Yes","No")) -> No
J13: =IF(OR($G13="",$H13="",$G13=0),"",$H13/$G13) | Q13: =IF($A13="","",IF(SUMPRODUCT(MAX((community_cores_FS!$B$5:$B$597=$A13)*community_cores_FS!$F$5:$F$597))=0,"",SUMPRODUCT(MAX((community_cores_FS!$B$5:$B$597=$A13)*community_cores_FS!$F$5:$F$597)))) | R13: =IF($A13="","",IFERROR(SUMIFS(community_cores_FS!$P$5:$P$597,community_cores_FS!$B$5:$B$597,$A13),"")) | S13: =IF($A13="","",IFERROR(SUMIFS(community_cores_FS!$Q$5:$Q$597,community_cores_FS!$B$5:$B$597,$A13),"")) | T13: =IF(NOT(ISNUMBER($Q13)),"",IF($Q13>=REFERENCE_DEPTH_CM,"Yes","No")) | U13: =IF($A13="","",IF(AND($B13<>"",COUNTIF('1. Plot & Site Log'!$A$5:$A$64,$B13)=0),"Plot ID not in Plot & Site Log. ","")&IF(NOT(ISNUMBER($Q13)),"No peat sections logged for this core. ","")&IF($T13="No","Core stops short of the reference depth, so its reference-depth stock is an underestimate. Its full-profile stock is still valid. ","")&IF($L13="No","Core did not reach the mineral contact — the full-profile stock is a MINIMUM, not the whole store. ","")&IF(AND(ISNUMBER($K13),$K13<PEATLAND_MIN_DEPTH_CM),"Organic depth under "&PEATLAND_MIN_DEPTH_CM&" cm: by the guide's definition this is not peatland. Report it, but say so. ","")&IF(AND(ISNUMBER($J13),$J13<QC_RECOVERY_MIN),"Recovered only "&TEXT($J13,"0%")&" of the bore depth — the chamber probably did not fill completely. Material is missing, which is not the same as compaction. ","")&IF(AND(ISNUMBER($J13),$J13>1.05),"Recovered more than the bore depth — check the two measurements. ","")&IF(AND(ISNUMBER($I13),$I13>2),"Surface compaction of "&$I13&" cm: depths in this core sit shallower than in the ground, so depth-limited stock is biased. Full-profile stock is unaffected. ",""))
J14: =IF(OR($G14="",$H14="",$G14=0),"",$H14/$G14) | Q14: =IF($A14="","",IF(SUMPRODUCT(MAX((community_cores_FS!$B$5:$B$597=$A14)*community_cores_FS!$F$5:$F$597))=0,"",SUMPRODUCT(MAX((community_cores_FS!$B$5:$B$597=$A14)*community_cores_FS!$F$5:$F$597)))) | R14: =IF($A14="","",IFERROR(SUMIFS(community_cores_FS!$P$5:$P$597,community_cores_FS!$B$5:$B$597,$A14),"")) | S14: =IF($A14="","",IFERROR(SUMIFS(community_cores_FS!$Q$5:$Q$597,community_cores_FS!$B$5:$B$597,$A14),"")) | T14: =IF(NOT(ISNUMBER($Q14)),"",IF($Q14>=REFERENCE_DEPTH_CM,"Yes","No")) | U14: =IF($A14="","",IF(AND($B14<>"",COUNTIF('1. Plot & Site Log'!$A$5:$A$64,$B14)=0),"Plot ID not in Plot & Site Log. ","")&IF(NOT(ISNUMBER($Q14)),"No peat sections logged for this core. ","")&IF($T14="No","Core stops short of the reference depth, so its reference-depth stock is an underestimate. Its full-profile stock is still valid. ","")&IF($L14="No","Core did not reach the mineral contact — the full-profile stock is a MINIMUM, not the whole store. ","")&IF(AND(ISNUMBER($K14),$K14<PEATLAND_MIN_DEPTH_CM),"Organic depth under "&PEATLAND_MIN_DEPTH_CM&" cm: by the guide's definition this is not peatland. Report it, but say so. ","")&IF(AND(ISNUMBER($J14),$J14<QC_RECOVERY_MIN),"Recovered only "&TEXT($J14,"0%")&" of the bore depth — the chamber probably did not fill completely. Material is missing, which is not the same as compaction. ","")&IF(AND(ISNUMBER($J14),$J14>1.05),"Recovered more than the bore depth — check the two measurements. ","")&IF(AND(ISNUMBER($I14),$I14>2),"Surface compaction of "&$I14&" cm: depths in this core sit shallower than in the ground, so depth-limited stock is biased. Full-profile stock is unaffected. ",""))
J15: =IF(OR($G15="",$H15="",$G15=0),"",$H15/$G15) | Q15: =IF($A15="","",IF(SUMPRODUCT(MAX((community_cores_FS!$B$5:$B$597=$A15)*community_cores_FS!$F$5:$F$597))=0,"",SUMPRODUCT(MAX((community_cores_FS!$B$5:$B$597=$A15)*community_cores_FS!$F$5:$F$597)))) | R15: =IF($A15="","",IFERROR(SUMIFS(community_cores_FS!$P$5:$P$597,community_cores_FS!$B$5:$B$597,$A15),"")) | S15: =IF($A15="","",IFERROR(SUMIFS(community_cores_FS!$Q$5:$Q$597,community_cores_FS!$B$5:$B$597,$A15),"")) | T15: =IF(NOT(ISNUMBER($Q15)),"",IF($Q15>=REFERENCE_DEPTH_CM,"Yes","No")) | U15: =IF($A15="","",IF(AND($B15<>"",COUNTIF('1. Plot & Site Log'!$A$5:$A$64,$B15)=0),"Plot ID not in Plot & Site Log. ","")&IF(NOT(ISNUMBER($Q15)),"No peat sections logged for this core. ","")&IF($T15="No","Core stops short of the reference depth, so its reference-depth stock is an underestimate. Its full-profile stock is still valid. ","")&IF($L15="No","Core did not reach the mineral contact — the full-profile stock is a MINIMUM, not the whole store. ","")&IF(AND(ISNUMBER($K15),$K15<PEATLAND_MIN_DEPTH_CM),"Organic depth under "&PEATLAND_MIN_DEPTH_CM&" cm: by the guide's definition this is not peatland. Report it, but say so. ","")&IF(AND(ISNUMBER($J15),$J15<QC_RECOVERY_MIN),"Recovered only "&TEXT($J15,"0%")&" of the bore depth — the chamber probably did not fill completely. Material is missing, which is not the same as compaction. ","")&IF(AND(ISNUMBER($J15),$J15>1.05),"Recovered more than the bore depth — check the two measurements. ","")&IF(AND(ISNUMBER($I15),$I15>2),"Surface compaction of "&$I15&" cm: depths in this core sit shallower than in the ground, so depth-limited stock is biased. Full-profile stock is unaffected. ",""))
J16: =IF(OR($G16="",$H16="",$G16=0),"",$H16/$G16) | Q16: =IF($A16="","",IF(SUMPRODUCT(MAX((community_cores_FS!$B$5:$B$597=$A16)*community_cores_FS!$F$5:$F$597))=0,"",SUMPRODUCT(MAX((community_cores_FS!$B$5:$B$597=$A16)*community_cores_FS!$F$5:$F$597)))) | R16: =IF($A16="","",IFERROR(SUMIFS(community_cores_FS!$P$5:$P$597,community_cores_FS!$B$5:$B$597,$A16),"")) | S16: =IF($A16="","",IFERROR(SUMIFS(community_cores_FS!$Q$5:$Q$597,community_cores_FS!$B$5:$B$597,$A16),"")) | T16: =IF(NOT(ISNUMBER($Q16)),"",IF($Q16>=REFERENCE_DEPTH_CM,"Yes","No")) | U16: =IF($A16="","",IF(AND($B16<>"",COUNTIF('1. Plot & Site Log'!$A$5:$A$64,$B16)=0),"Plot ID not in Plot & Site Log. ","")&IF(NOT(ISNUMBER($Q16)),"No peat sections logged for this core. ","")&IF($T16="No","Core stops short of the reference depth, so its reference-depth stock is an underestimate. Its full-profile stock is still valid. ","")&IF($L16="No","Core did not reach the mineral contact — the full-profile stock is a MINIMUM, not the whole store. ","")&IF(AND(ISNUMBER($K16),$K16<PEATLAND_MIN_DEPTH_CM),"Organic depth under "&PEATLAND_MIN_DEPTH_CM&" cm: by the guide's definition this is not peatland. Report it, but say so. ","")&IF(AND(ISNUMBER($J16),$J16<QC_RECOVERY_MIN),"Recovered only "&TEXT($J16,"0%")&" of the bore depth — the chamber probably did not fill completely. Material is missing, which is not the same as compaction. ","")&IF(AND(ISNUMBER($J16),$J16>1.05),"Recovered more than the bore depth — check the two measurements. ","")&IF(AND(ISNUMBER($I16),$I16>2),"Surface compaction of "&$I16&" cm: depths in this core sit shallower than in the ground, so depth-limited stock is biased. Full-profile stock is unaffected. ",""))
J17: =IF(OR($G17="",$H17="",$G17=0),"",$H17/$G17) | Q17: =IF($A17="","",IF(SUMPRODUCT(MAX((community_cores_FS!$B$5:$B$597=$A17)*community_cores_FS!$F$5:$F$597))=0,"",SUMPRODUCT(MAX((community_cores_FS!$B$5:$B$597=$A17)*community_cores_FS!$F$5:$F$597)))) | R17: =IF($A17="","",IFERROR(SUMIFS(community_cores_FS!$P$5:$P$597,community_cores_FS!$B$5:$B$597,$A17),"")) | S17: =IF($A17="","",IFERROR(SUMIFS(community_cores_FS!$Q$5:$Q$597,community_cores_FS!$B$5:$B$597,$A17),"")) | T17: =IF(NOT(ISNUMBER($Q17)),"",IF($Q17>=REFERENCE_DEPTH_CM,"Yes","No")) | U17: =IF($A17="","",IF(AND($B17<>"",COUNTIF('1. Plot & Site Log'!$A$5:$A$64,$B17)=0),"Plot ID not in Plot & Site Log. ","")&IF(NOT(ISNUMBER($Q17)),"No peat sections logged for this core. ","")&IF($T17="No","Core stops short of the reference depth, so its reference-depth stock is an underestimate. Its full-profile stock is still valid. ","")&IF($L17="No","Core did not reach the mineral contact — the full-profile stock is a MINIMUM, not the whole store. ","")&IF(AND(ISNUMBER($K17),$K17<PEATLAND_MIN_DEPTH_CM),"Organic depth under "&PEATLAND_MIN_DEPTH_CM&" cm: by the guide's definition this is not peatland. Report it, but say so. ","")&IF(AND(ISNUMBER($J17),$J17<QC_RECOVERY_MIN),"Recovered only "&TEXT($J17,"0%")&" of the bore depth — the chamber probably did not fill completely. Material is missing, which is not the same as compaction. ","")&IF(AND(ISNUMBER($J17),$J17>1.05),"Recovered more than the bore depth — check the two measurements. ","")&IF(AND(ISNUMBER($I17),$I17>2),"Surface compaction of "&$I17&" cm: depths in this core sit shallower than in the ground, so depth-limited stock is biased. Full-profile stock is unaffected. ",""))
J18: =IF(OR($G18="",$H18="",$G18=0),"",$H18/$G18) | Q18: =IF($A18="","",IF(SUMPRODUCT(MAX((community_cores_FS!$B$5:$B$597=$A18)*community_cores_FS!$F$5:$F$597))=0,"",SUMPRODUCT(MAX((community_cores_FS!$B$5:$B$597=$A18)*community_cores_FS!$F$5:$F$597)))) | R18: =IF($A18="","",IFERROR(SUMIFS(community_cores_FS!$P$5:$P$597,community_cores_FS!$B$5:$B$597,$A18),"")) | S18: =IF($A18="","",IFERROR(SUMIFS(community_cores_FS!$Q$5:$Q$597,community_cores_FS!$B$5:$B$597,$A18),"")) | T18: =IF(NOT(ISNUMBER($Q18)),"",IF($Q18>=REFERENCE_DEPTH_CM,"Yes","No")) | U18: =IF($A18="","",IF(AND($B18<>"",COUNTIF('1. Plot & Site Log'!$A$5:$A$64,$B18)=0),"Plot ID not in Plot & Site Log. ","")&IF(NOT(ISNUMBER($Q18)),"No peat sections logged for this core. ","")&IF($T18="No","Core stops short of the reference depth, so its reference-depth stock is an underestimate. Its full-profile stock is still valid. ","")&IF($L18="No","Core did not reach the mineral contact — the full-profile stock is a MINIMUM, not the whole store. ","")&IF(AND(ISNUMBER($K18),$K18<PEATLAND_MIN_DEPTH_CM),"Organic depth under "&PEATLAND_MIN_DEPTH_CM&" cm: by the guide's definition this is not peatland. Report it, but say so. ","")&IF(AND(ISNUMBER($J18),$J18<QC_RECOVERY_MIN),"Recovered only "&TEXT($J18,"0%")&" of the bore depth — the chamber probably did not fill completely. Material is missing, which is not the same as compaction. ","")&IF(AND(ISNUMBER($J18),$J18>1.05),"Recovered more than the bore depth — check the two measurements. ","")&IF(AND(ISNUMBER($I18),$I18>2),"Surface compaction of "&$I18&" cm: depths in this core sit shallower than in the ground, so depth-limited stock is biased. Full-profile stock is unaffected. ",""))
J19: =IF(OR($G19="",$H19="",$G19=0),"",$H19/$G19) | Q19: =IF($A19="","",IF(SUMPRODUCT(MAX((community_cores_FS!$B$5:$B$597=$A19)*community_cores_FS!$F$5:$F$597))=0,"",SUMPRODUCT(MAX((community_cores_FS!$B$5:$B$597=$A19)*community_cores_FS!$F$5:$F$597)))) | R19: =IF($A19="","",IFERROR(SUMIFS(community_cores_FS!$P$5:$P$597,community_cores_FS!$B$5:$B$597,$A19),"")) | S19: =IF($A19="","",IFERROR(SUMIFS(community_cores_FS!$Q$5:$Q$597,community_cores_FS!$B$5:$B$597,$A19),"")) | T19: =IF(NOT(ISNUMBER($Q19)),"",IF($Q19>=REFERENCE_DEPTH_CM,"Yes","No")) | U19: =IF($A19="","",IF(AND($B19<>"",COUNTIF('1. Plot & Site Log'!$A$5:$A$64,$B19)=0),"Plot ID not in Plot & Site Log. ","")&IF(NOT(ISNUMBER($Q19)),"No peat sections logged for this core. ","")&IF($T19="No","Core stops short of the reference depth, so its reference-depth stock is an underestimate. Its full-profile stock is still valid. ","")&IF($L19="No","Core did not reach the mineral contact — the full-profile stock is a MINIMUM, not the whole store. ","")&IF(AND(ISNUMBER($K19),$K19<PEATLAND_MIN_DEPTH_CM),"Organic depth under "&PEATLAND_MIN_DEPTH_CM&" cm: by the guide's definition this is not peatland. Report it, but say so. ","")&IF(AND(ISNUMBER($J19),$J19<QC_RECOVERY_MIN),"Recovered only "&TEXT($J19,"0%")&" of the bore depth — the chamber probably did not fill completely. Material is missing, which is not the same as compaction. ","")&IF(AND(ISNUMBER($J19),$J19>1.05),"Recovered more than the bore depth — check the two measurements. ","")&IF(AND(ISNUMBER($I19),$I19>2),"Surface compaction of "&$I19&" cm: depths in this core sit shallower than in the ground, so depth-limited stock is biased. Full-profile stock is unaffected. ",""))
J20: =IF(OR($G20="",$H20="",$G20=0),"",$H20/$G20) | Q20: =IF($A20="","",IF(SUMPRODUCT(MAX((community_cores_FS!$B$5:$B$597=$A20)*community_cores_FS!$F$5:$F$597))=0,"",SUMPRODUCT(MAX((community_cores_FS!$B$5:$B$597=$A20)*community_cores_FS!$F$5:$F$597)))) | R20: =IF($A20="","",IFERROR(SUMIFS(community_cores_FS!$P$5:$P$597,community_cores_FS!$B$5:$B$597,$A20),"")) | S20: =IF($A20="","",IFERROR(SUMIFS(community_cores_FS!$Q$5:$Q$597,community_cores_FS!$B$5:$B$597,$A20),"")) | T20: =IF(NOT(ISNUMBER($Q20)),"",IF($Q20>=REFERENCE_DEPTH_CM,"Yes","No")) | U20: =IF($A20="","",IF(AND($B20<>"",COUNTIF('1. Plot & Site Log'!$A$5:$A$64,$B20)=0),"Plot ID not in Plot & Site Log. ","")&IF(NOT(ISNUMBER($Q20)),"No peat sections logged for this core. ","")&IF($T20="No","Core stops short of the reference depth, so its reference-depth stock is an underestimate. Its full-profile stock is still valid. ","")&IF($L20="No","Core did not reach the mineral contact — the full-profile stock is a MINIMUM, not the whole store. ","")&IF(AND(ISNUMBER($K20),$K20<PEATLAND_MIN_DEPTH_CM),"Organic depth under "&PEATLAND_MIN_DEPTH_CM&" cm: by the guide's definition this is not peatland. Report it, but say so. ","")&IF(AND(ISNUMBER($J20),$J20<QC_RECOVERY_MIN),"Recovered only "&TEXT($J20,"0%")&" of the bore depth — the chamber probably did not fill completely. Material is missing, which is not the same as compaction. ","")&IF(AND(ISNUMBER($J20),$J20>1.05),"Recovered more than the bore depth — check the two measurements. ","")&IF(AND(ISNUMBER($I20),$I20>2),"Surface compaction of "&$I20&" cm: depths in this core sit shallower than in the ground, so depth-limited stock is biased. Full-profile stock is unaffected. ",""))
J21: =IF(OR($G21="",$H21="",$G21=0),"",$H21/$G21) | Q21: =IF($A21="","",IF(SUMPRODUCT(MAX((community_cores_FS!$B$5:$B$597=$A21)*community_cores_FS!$F$5:$F$597))=0,"",SUMPRODUCT(MAX((community_cores_FS!$B$5:$B$597=$A21)*community_cores_FS!$F$5:$F$597)))) | R21: =IF($A21="","",IFERROR(SUMIFS(community_cores_FS!$P$5:$P$597,community_cores_FS!$B$5:$B$597,$A21),"")) | S21: =IF($A21="","",IFERROR(SUMIFS(community_cores_FS!$Q$5:$Q$597,community_cores_FS!$B$5:$B$597,$A21),"")) | T21: =IF(NOT(ISNUMBER($Q21)),"",IF($Q21>=REFERENCE_DEPTH_CM,"Yes","No")) | U21: =IF($A21="","",IF(AND($B21<>"",COUNTIF('1. Plot & Site Log'!$A$5:$A$64,$B21)=0),"Plot ID not in Plot & Site Log. ","")&IF(NOT(ISNUMBER($Q21)),"No peat sections logged for this core. ","")&IF($T21="No","Core stops short of the reference depth, so its reference-depth stock is an underestimate. Its full-profile stock is still valid. ","")&IF($L21="No","Core did not reach the mineral contact — the full-profile stock is a MINIMUM, not the whole store. ","")&IF(AND(ISNUMBER($K21),$K21<PEATLAND_MIN_DEPTH_CM),"Organic depth under "&PEATLAND_MIN_DEPTH_CM&" cm: by the guide's definition this is not peatland. Report it, but say so. ","")&IF(AND(ISNUMBER($J21),$J21<QC_RECOVERY_MIN),"Recovered only "&TEXT($J21,"0%")&" of the bore depth — the chamber probably did not fill completely. Material is missing, which is not the same as compaction. ","")&IF(AND(ISNUMBER($J21),$J21>1.05),"Recovered more than the bore depth — check the two measurements. ","")&IF(AND(ISNUMBER($I21),$I21>2),"Surface compaction of "&$I21&" cm: depths in this core sit shallower than in the ground, so depth-limited stock is biased. Full-profile stock is unaffected. ",""))
J22: =IF(OR($G22="",$H22="",$G22=0),"",$H22/$G22) | Q22: =IF($A22="","",IF(SUMPRODUCT(MAX((community_cores_FS!$B$5:$B$597=$A22)*community_cores_FS!$F$5:$F$597))=0,"",SUMPRODUCT(MAX((community_cores_FS!$B$5:$B$597=$A22)*community_cores_FS!$F$5:$F$597)))) | R22: =IF($A22="","",IFERROR(SUMIFS(community_cores_FS!$P$5:$P$597,community_cores_FS!$B$5:$B$597,$A22),"")) | S22: =IF($A22="","",IFERROR(SUMIFS(community_cores_FS!$Q$5:$Q$597,community_cores_FS!$B$5:$B$597,$A22),"")) | T22: =IF(NOT(ISNUMBER($Q22)),"",IF($Q22>=REFERENCE_DEPTH_CM,"Yes","No")) | U22: =IF($A22="","",IF(AND($B22<>"",COUNTIF('1. Plot & Site Log'!$A$5:$A$64,$B22)=0),"Plot ID not in Plot & Site Log. ","")&IF(NOT(ISNUMBER($Q22)),"No peat sections logged for this core. ","")&IF($T22="No","Core stops short of the reference depth, so its reference-depth stock is an underestimate. Its full-profile stock is still valid. ","")&IF($L22="No","Core did not reach the mineral contact — the full-profile stock is a MINIMUM, not the whole store. ","")&IF(AND(ISNUMBER($K22),$K22<PEATLAND_MIN_DEPTH_CM),"Organic depth under "&PEATLAND_MIN_DEPTH_CM&" cm: by the guide's definition this is not peatland. Report it, but say so. ","")&IF(AND(ISNUMBER($J22),$J22<QC_RECOVERY_MIN),"Recovered only "&TEXT($J22,"0%")&" of the bore depth — the chamber probably did not fill completely. Material is missing, which is not the same as compaction. ","")&IF(AND(ISNUMBER($J22),$J22>1.05),"Recovered more than the bore depth — check the two measurements. ","")&IF(AND(ISNUMBER($I22),$I22>2),"Surface compaction of "&$I22&" cm: depths in this core sit shallower than in the ground, so depth-limited stock is biased. Full-profile stock is unaffected. ",""))
J23: =IF(OR($G23="",$H23="",$G23=0),"",$H23/$G23) | Q23: =IF($A23="","",IF(SUMPRODUCT(MAX((community_cores_FS!$B$5:$B$597=$A23)*community_cores_FS!$F$5:$F$597))=0,"",SUMPRODUCT(MAX((community_cores_FS!$B$5:$B$597=$A23)*community_cores_FS!$F$5:$F$597)))) | R23: =IF($A23="","",IFERROR(SUMIFS(community_cores_FS!$P$5:$P$597,community_cores_FS!$B$5:$B$597,$A23),"")) | S23: =IF($A23="","",IFERROR(SUMIFS(community_cores_FS!$Q$5:$Q$597,community_cores_FS!$B$5:$B$597,$A23),"")) | T23: =IF(NOT(ISNUMBER($Q23)),"",IF($Q23>=REFERENCE_DEPTH_CM,"Yes","No")) | U23: =IF($A23="","",IF(AND($B23<>"",COUNTIF('1. Plot & Site Log'!$A$5:$A$64,$B23)=0),"Plot ID not in Plot & Site Log. ","")&IF(NOT(ISNUMBER($Q23)),"No peat sections logged for this core. ","")&IF($T23="No","Core stops short of the reference depth, so its reference-depth stock is an underestimate. Its full-profile stock is still valid. ","")&IF($L23="No","Core did not reach the mineral contact — the full-profile stock is a MINIMUM, not the whole store. ","")&IF(AND(ISNUMBER($K23),$K23<PEATLAND_MIN_DEPTH_CM),"Organic depth under "&PEATLAND_MIN_DEPTH_CM&" cm: by the guide's definition this is not peatland. Report it, but say so. ","")&IF(AND(ISNUMBER($J23),$J23<QC_RECOVERY_MIN),"Recovered only "&TEXT($J23,"0%")&" of the bore depth — the chamber probably did not fill completely. Material is missing, which is not the same as compaction. ","")&IF(AND(ISNUMBER($J23),$J23>1.05),"Recovered more than the bore depth — check the two measurements. ","")&IF(AND(ISNUMBER($I23),$I23>2),"Surface compaction of "&$I23&" cm: depths in this core sit shallower than in the ground, so depth-limited stock is biased. Full-profile stock is unaffected. ",""))
J24: =IF(OR($G24="",$H24="",$G24=0),"",$H24/$G24) | Q24: =IF($A24="","",IF(SUMPRODUCT(MAX((community_cores_FS!$B$5:$B$597=$A24)*community_cores_FS!$F$5:$F$597))=0,"",SUMPRODUCT(MAX((community_cores_FS!$B$5:$B$597=$A24)*community_cores_FS!$F$5:$F$597)))) | R24: =IF($A24="","",IFERROR(SUMIFS(community_cores_FS!$P$5:$P$597,community_cores_FS!$B$5:$B$597,$A24),"")) | S24: =IF($A24="","",IFERROR(SUMIFS(community_cores_FS!$Q$5:$Q$597,community_cores_FS!$B$5:$B$597,$A24),"")) | T24: =IF(NOT(ISNUMBER($Q24)),"",IF($Q24>=REFERENCE_DEPTH_CM,"Yes","No")) | U24: =IF($A24="","",IF(AND($B24<>"",COUNTIF('1. Plot & Site Log'!$A$5:$A$64,$B24)=0),"Plot ID not in Plot & Site Log. ","")&IF(NOT(ISNUMBER($Q24)),"No peat sections logged for this core. ","")&IF($T24="No","Core stops short of the reference depth, so its reference-depth stock is an underestimate. Its full-profile stock is still valid. ","")&IF($L24="No","Core did not reach the mineral contact — the full-profile stock is a MINIMUM, not the whole store. ","")&IF(AND(ISNUMBER($K24),$K24<PEATLAND_MIN_DEPTH_CM),"Organic depth under "&PEATLAND_MIN_DEPTH_CM&" cm: by the guide's definition this is not peatland. Report it, but say so. ","")&IF(AND(ISNUMBER($J24),$J24<QC_RECOVERY_MIN),"Recovered only "&TEXT($J24,"0%")&" of the bore depth — the chamber probably did not fill completely. Material is missing, which is not the same as compaction. ","")&IF(AND(ISNUMBER($J24),$J24>1.05),"Recovered more than the bore depth — check the two measurements. ","")&IF(AND(ISNUMBER($I24),$I24>2),"Surface compaction of "&$I24&" cm: depths in this core sit shallower than in the ground, so depth-limited stock is biased. Full-profile stock is unaffected. ",""))
... J124: =IF(OR($G124="",$H124="",$G124=0),"",$H124/$G124) | Q124: =IF($A124="","",IF(SUMPRODUCT(MAX((community_cores_FS!$B$5:$B$597=$A124)*community_cores_FS!$F$5:$F$597))=0,"",SUMPRODUCT(MAX((community_cores_FS!$B$5:$B$597=$A124)*community_cores_FS!$F$5:$F$597)))) | R124: =IF($A124="","",IFERROR(SUMIFS(community_cores_FS!$P$5:$P$597,community_cores_FS!$B$5:$B$597,$A124),"")) | S124: =IF($A124="","",IFERROR(SUMIFS(community_cores_FS!$Q$5:$Q$597,community_cores_FS!$B$5:$B$597,$A124),"")) | T124: =IF(NOT(ISNUMBER($Q124)),"",IF($Q124>=REFERENCE_DEPTH_CM,"Yes","No")) | U124: =IF($A124="","",IF(AND($B124<>"",COUNTIF('1. Plot & Site Log'!$A$5:$A$64,$B124)=0),"Plot ID not in Plot & Site Log. ","")&IF(NOT(ISNUMBER($Q124)),"No peat sections logged for this core. ","")&IF($T124="No","Core stops short of the reference depth, so its reference-depth stock is an underestimate. Its full-profile stock is still valid. ","")&IF($L124="No","Core did not reach the mineral contact — the full-profile stock is a MINIMUM, not the whole store. ","")&IF(AND(ISNUMBER($K124),$K124<PEATLAND_MIN_DEPTH_CM),"Organic depth under "&PEATLAND_MIN_DEPTH_CM&" cm: by the guide's definition this is not peatland. Report it, but say so. ","")&IF(AND(ISNUMBER($J124),$J124<QC_RECOVERY_MIN),"Recovered only "&TEXT($J124,"0%")&" of the bore depth — the chamber probably did not fill completely. Material is missing, which is not the same as compaction. ","")&IF(AND(ISNUMBER($J124),$J124>1.05),"Recovered more than the bore depth — check the two measurements. ","")&IF(AND(ISNUMBER($I124),$I124>2),"Surface compaction of "&$I124&" cm: depths in this core sit shallower than in the ground, so depth-limited stock is biased. Full-profile stock is unaffected. ",""))

Sheet community_cores_FS
A1: SOIL CORE DATA — SIMULATED
A2: SIMULATED. Includes wetland peat and forest organic/mineral horizons. Depths start at ground surface. Water content is percent of fresh mass. pH, nitrogen, C:N and horizon are retained in Notes and in the companion CSV.
A4: Plot ID | B4: Core ID | C4: Drive # | D4: Section ID | E4: Top depth (cm) | F4: Bottom depth (cm) | G4: Thickness (cm) | H4: von Post | I4: Bulk density basis | J4: Bulk density (g/cm³) | K4: Water content (%) | L4: LOI₅₅₀ (%) | M4: Organic carbon (%) | N4: Carbon % used | O4: Thickness within reference depth (cm) | P4: Stock, full thickness (kg C/m²) | Q4: Stock to reference depth (kg C/m²) | R4: _stock per cm | S4: Cumulative carbon to base (kg C/m²) | T4: QC flags | U4: Notes
A5: PM-01-A | B5: PM-01-A | C5: 1 | D5: PM-01-A | E5: 0 | F5: 14.5 | G5: =IF(AND(ISNUMBER($E5),ISNUMBER($F5)),$F5-$E5,"") -> 14.5 | I5: Whole sample / sample volume | J5: 0.0929 | L5: 39.1 | M5: 22.7 | N5: =IF($M5<>"",$M5,IF($L5<>"",$L5*CARBON_FRACTION_OM,"")) -> 22.7 | O5: =IF(AND(ISNUMBER($E5),ISNUMBER($F5)),MAX(0,MIN($F5,REFERENCE_DEPTH_CM)-MIN($E5,REFERENCE_DEPTH_CM)),"") -> 14.5 | P5: =IF(AND(ISNUMBER($J5),ISNUMBER($N5),ISNUMBER($G5)),$J5*($N5/100)*$G5*10,"") -> 3.0578035 | Q5: =IF(AND(ISNUMBER($J5),ISNUMBER($N5),ISNUMBER($O5)),$J5*($N5/100)*$O5*10,"") -> 3.0578035 | R5: =IF(OR(NOT(ISNUMBER($P5)),NOT(ISNUMBER($G5)),$G5=0),0,$P5/$G5) -> 0.210883 | S5: =IF(OR($B5="",NOT(ISNUMBER($F5))),"",SUMIFS(community_cores_FS!$P$5:$P$597,community_cores_FS!$B$5:$B$597,$B5,community_cores_FS!$F$5:$F$597,"<="&$F5)) -> 3.0578035 | T5: =IF(OR($B5="",$J5="",$M5=""),"Missing input",IF(OR($J5<0.02,$J5>1.2,$M5<0,$M5>60),"Check density or carbon units",IF($F5>REFERENCE_DEPTH_CM,"Below reference depth; included in sampled profile only","")))
A6: PM-02-A | B6: PM-02-A | C6: 1 | D6: PM-02-A-1 | E6: 0 | F6: 15.2 | G6: =IF(AND(ISNUMBER($E6),ISNUMBER($F6)),$F6-$E6,"") -> 15.2 | H6: H2 | I6: Whole sample / sample volume | J6: 0.0827 | L6: 39.1 | M6: 22.7 | N6: =IF($M6<>"",$M6,IF($L6<>"",$L6*CARBON_FRACTION_OM,"")) -> 22.7 | O6: =IF(AND(ISNUMBER($E6),ISNUMBER($F6)),MAX(0,MIN($F6,REFERENCE_DEPTH_CM)-MIN($E6,REFERENCE_DEPTH_CM)),"") -> 15.2 | P6: =IF(AND(ISNUMBER($J6),ISNUMBER($N6),ISNUMBER($G6)),$J6*($N6/100)*$G6*10,"") -> 2.8534808 | Q6: =IF(AND(ISNUMBER($J6),ISNUMBER($N6),ISNUMBER($O6)),$J6*($N6/100)*$O6*10,"") -> 2.8534808 | R6: =IF(OR(NOT(ISNUMBER($P6)),NOT(ISNUMBER($G6)),$G6=0),0,$P6/$G6) -> 0.187729 | S6: =IF(OR($B6="",NOT(ISNUMBER($F6))),"",SUMIFS(community_cores_FS!$P$5:$P$597,community_cores_FS!$B$5:$B$597,$B6,community_cores_FS!$F$5:$F$597,"<="&$F6)) -> 2.8534808 | T6: =IF(OR($B6="",$J6="",$M6=""),"Missing input",IF(OR($J6<0.02,$J6>1.2,$M6<0,$M6>60),"Check density or carbon units",IF($F6>REFERENCE_DEPTH_CM,"Below reference depth; included in sampled profile only","")))
A7: PM-02-A | B7: PM-02-A | C7: 1 | D7: PM-02-A-2 | E7: 15.2 | F7: 20.7 | G7: =IF(AND(ISNUMBER($E7),ISNUMBER($F7)),$F7-$E7,"") -> 5.5 | I7: Whole sample / sample volume | J7: 0.2662 | L7: 2.71 | M7: 1.57 | N7: =IF($M7<>"",$M7,IF($L7<>"",$L7*CARBON_FRACTION_OM,"")) -> 1.57 | O7: =IF(AND(ISNUMBER($E7),ISNUMBER($F7)),MAX(0,MIN($F7,REFERENCE_DEPTH_CM)-MIN($E7,REFERENCE_DEPTH_CM)),"") -> 5.5 | P7: =IF(AND(ISNUMBER($J7),ISNUMBER($N7),ISNUMBER($G7)),$J7*($N7/100)*$G7*10,"") -> 0.2298637 | Q7: =IF(AND(ISNUMBER($J7),ISNUMBER($N7),ISNUMBER($O7)),$J7*($N7/100)*$O7*10,"") -> 0.2298637 | R7: =IF(OR(NOT(ISNUMBER($P7)),NOT(ISNUMBER($G7)),$G7=0),0,$P7/$G7) -> 0.0417934 | S7: =IF(OR($B7="",NOT(ISNUMBER($F7))),"",SUMIFS(community_cores_FS!$P$5:$P$597,community_cores_FS!$B$5:$B$597,$B7,community_cores_FS!$F$5:$F$597,"<="&$F7)) -> 3.0833445 | T7: =IF(OR($B7="",$J7="",$M7=""),"Missing input",IF(OR($J7<0.02,$J7>1.2,$M7<0,$M7>60),"Check density or carbon units",IF($F7>REFERENCE_DEPTH_CM,"Below reference depth; included in sampled profile only","")))
A8: PM-03-A | B8: PM-03-A | C8: 1 | D8: PM-03-A-1 | E8: 0 | F8: 8.625 | G8: =IF(AND(ISNUMBER($E8),ISNUMBER($F8)),$F8-$E8,"") -> 8.625 | I8: Whole sample / sample volume | J8: 0.0501 | L8: 62.9 | M8: 36.5 | N8: =IF($M8<>"",$M8,IF($L8<>"",$L8*CARBON_FRACTION_OM,"")) -> 36.5 | O8: =IF(AND(ISNUMBER($E8),ISNUMBER($F8)),MAX(0,MIN($F8,REFERENCE_DEPTH_CM)-MIN($E8,REFERENCE_DEPTH_CM)),"") -> 8.625 | P8: =IF(AND(ISNUMBER($J8),ISNUMBER($N8),ISNUMBER($G8)),$J8*($N8/100)*$G8*10,"") -> 1.5772106 | Q8: =IF(AND(ISNUMBER($J8),ISNUMBER($N8),ISNUMBER($O8)),$J8*($N8/100)*$O8*10,"") -> 1.5772106 | R8: =IF(OR(NOT(ISNUMBER($P8)),NOT(ISNUMBER($G8)),$G8=0),0,$P8/$G8) -> 0.182865 | S8: =IF(OR($B8="",NOT(ISNUMBER($F8))),"",SUMIFS(community_cores_FS!$P$5:$P$597,community_cores_FS!$B$5:$B$597,$B8,community_cores_FS!$F$5:$F$597,"<="&$F8)) -> 1.5772106 | T8: =IF(OR($B8="",$J8="",$M8=""),"Missing input",IF(OR($J8<0.02,$J8>1.2,$M8<0,$M8>60),"Check density or carbon units",IF($F8>REFERENCE_DEPTH_CM,"Below reference depth; included in sampled profile only","")))
A9: PM-03-A | B9: PM-03-A | C9: 1 | D9: PM-03-A-2 | E9: 8.625 | F9: 17.725 | G9: =IF(AND(ISNUMBER($E9),ISNUMBER($F9)),$F9-$E9,"") -> 9.1 | I9: Whole sample / sample volume | J9: 0.0759 | L9: 73.1 | M9: 42.4 | N9: =IF($M9<>"",$M9,IF($L9<>"",$L9*CARBON_FRACTION_OM,"")) -> 42.4 | O9: =IF(AND(ISNUMBER($E9),ISNUMBER($F9)),MAX(0,MIN($F9,REFERENCE_DEPTH_CM)-MIN($E9,REFERENCE_DEPTH_CM)),"") -> 9.1 | P9: =IF(AND(ISNUMBER($J9),ISNUMBER($N9),ISNUMBER($G9)),$J9*($N9/100)*$G9*10,"") -> 2.9285256 | Q9: =IF(AND(ISNUMBER($J9),ISNUMBER($N9),ISNUMBER($O9)),$J9*($N9/100)*$O9*10,"") -> 2.9285256 | R9: =IF(OR(NOT(ISNUMBER($P9)),NOT(ISNUMBER($G9)),$G9=0),0,$P9/$G9) -> 0.321816 | S9: =IF(OR($B9="",NOT(ISNUMBER($F9))),"",SUMIFS(community_cores_FS!$P$5:$P$597,community_cores_FS!$B$5:$B$597,$B9,community_cores_FS!$F$5:$F$597,"<="&$F9)) -> 4.5057362 | T9: =IF(OR($B9="",$J9="",$M9=""),"Missing input",IF(OR($J9<0.02,$J9>1.2,$M9<0,$M9>60),"Check density or carbon units",IF($F9>REFERENCE_DEPTH_CM,"Below reference depth; included in sampled profile only","")))
A10: PM-03-A | B10: PM-03-A | C10: 1 | D10: PM-03-A-3 | E10: 17.725 | F10: 25.225 | G10: =IF(AND(ISNUMBER($E10),ISNUMBER($F10)),$F10-$E10,"") -> 7.5 | I10: Whole sample / sample volume | J10: 0.1459 | L10: 67.1 | M10: 38.9 | N10: =IF($M10<>"",$M10,IF($L10<>"",$L10*CARBON_FRACTION_OM,"")) -> 38.9 | O10: =IF(AND(ISNUMBER($E10),ISNUMBER($F10)),MAX(0,MIN($F10,REFERENCE_DEPTH_CM)-MIN($E10,REFERENCE_DEPTH_CM)),"") -> 7.5 | P10: =IF(AND(ISNUMBER($J10),ISNUMBER($N10),ISNUMBER($G10)),$J10*($N10/100)*$G10*10,"") -> 4.2566325 | Q10: =IF(AND(ISNUMBER($J10),ISNUMBER($N10),ISNUMBER($O10)),$J10*($N10/100)*$O10*10,"") -> 4.2566325 | R10: =IF(OR(NOT(ISNUMBER($P10)),NOT(ISNUMBER($G10)),$G10=0),0,$P10/$G10) -> 0.567551 | S10: =IF(OR($B10="",NOT(ISNUMBER($F10))),"",SUMIFS(community_cores_FS!$P$5:$P$597,community_cores_FS!$B$5:$B$597,$B10,community_cores_FS!$F$5:$F$597,"<="&$F10)) -> 8.7623687 | T10: =IF(OR($B10="",$J10="",$M10=""),"Missing input",IF(OR($J10<0.02,$J10>1.2,$M10<0,$M10>60),"Check density or carbon units",IF($F10>REFERENCE_DEPTH_CM,"Below reference depth; included in sampled profile only","")))
A11: PM-03-A | B11: PM-03-A | C11: 1 | D11: PM-03-A-4 | E11: 25.225 | F11: 30.725 | G11: =IF(AND(ISNUMBER($E11),ISNUMBER($F11)),$F11-$E11,"") -> 5.5 | I11: Whole sample / sample volume | J11: 0.2287 | L11: 18.4 | M11: 10.7 | N11: =IF($M11<>"",$M11,IF($L11<>"",$L11*CARBON_FRACTION_OM,"")) -> 10.7 | O11: =IF(AND(ISNUMBER($E11),ISNUMBER($F11)),MAX(0,MIN($F11,REFERENCE_DEPTH_CM)-MIN($E11,REFERENCE_DEPTH_CM)),"") -> 5.5 | P11: =IF(AND(ISNUMBER($J11),ISNUMBER($N11),ISNUMBER($G11)),$J11*($N11/100)*$G11*10,"") -> 1.3458995 | Q11: =IF(AND(ISNUMBER($J11),ISNUMBER($N11),ISNUMBER($O11)),$J11*($N11/100)*$O11*10,"") -> 1.3458995 | R11: =IF(OR(NOT(ISNUMBER($P11)),NOT(ISNUMBER($G11)),$G11=0),0,$P11/$G11) -> 0.244709 | S11: =IF(OR($B11="",NOT(ISNUMBER($F11))),"",SUMIFS(community_cores_FS!$P$5:$P$597,community_cores_FS!$B$5:$B$597,$B11,community_cores_FS!$F$5:$F$597,"<="&$F11)) -> 10.108268 | T11: =IF(OR($B11="",$J11="",$M11=""),"Missing input",IF(OR($J11<0.02,$J11>1.2,$M11<0,$M11>60),"Check density or carbon units",IF($F11>REFERENCE_DEPTH_CM,"Below reference depth; included in sampled profile only","")))
A12: FS-05 | B12: FS-05 | C12: 1 | D12: FS-05-1 | E12: 0 | F12: 10 | G12: =IF(AND(ISNUMBER($E12),ISNUMBER($F12)),$F12-$E12,"") -> 10 | I12: Whole sample / sample volume | J12: 0.27948308 | L12: 15.6 | M12: 8.6 | N12: =IF($M12<>"",$M12,IF($L12<>"",$L12*CARBON_FRACTION_OM,"")) -> 8.6 | O12: =IF(AND(ISNUMBER($E12),ISNUMBER($F12)),MAX(0,MIN($F12,REFERENCE_DEPTH_CM)-MIN($E12,REFERENCE_DEPTH_CM)),"") -> 10 | P12: =IF(AND(ISNUMBER($J12),ISNUMBER($N12),ISNUMBER($G12)),$J12*($N12/100)*$G12*10,"") -> 2.4035545 | Q12: =IF(AND(ISNUMBER($J12),ISNUMBER($N12),ISNUMBER($O12)),$J12*($N12/100)*$O12*10,"") -> 2.4035545 | R12: =IF(OR(NOT(ISNUMBER($P12)),NOT(ISNUMBER($G12)),$G12=0),0,$P12/$G12) -> 0.24035545 | S12: =IF(OR($B12="",NOT(ISNUMBER($F12))),"",SUMIFS(community_cores_FS!$P$5:$P$597,community_cores_FS!$B$5:$B$597,$B12,community_cores_FS!$F$5:$F$597,"<="&$F12)) -> 2.4035545 | T12: =IF(OR($B12="",$J12="",$M12=""),"Missing input",IF(OR($J12<0.02,$J12>1.2,$M12<0,$M12>60),"Check density or carbon units",IF($F12>REFERENCE_DEPTH_CM,"Below reference depth; included in sampled profile only","")))
A13: FS-05 | B13: FS-05 | C13: 1 | D13: FS-05-2 | E13: 10 | F13: 20 | G13: =IF(AND(ISNUMBER($E13),ISNUMBER($F13)),$F13-$E13,"") -> 10 | I13: Whole sample / sample volume | J13: 2.0365201 | L13: 2.1 | M13: 1.1 | N13: =IF($M13<>"",$M13,IF($L13<>"",$L13*CARBON_FRACTION_OM,"")) -> 1.1 | O13: =IF(AND(ISNUMBER($E13),ISNUMBER($F13)),MAX(0,MIN($F13,REFERENCE_DEPTH_CM)-MIN($E13,REFERENCE_DEPTH_CM)),"") -> 10 | P13: =IF(AND(ISNUMBER($J13),ISNUMBER($N13),ISNUMBER($G13)),$J13*($N13/100)*$G13*10,"") -> 2.2401721 | Q13: =IF(AND(ISNUMBER($J13),ISNUMBER($N13),ISNUMBER($O13)),$J13*($N13/100)*$O13*10,"") -> 2.2401721 | R13: =IF(OR(NOT(ISNUMBER($P13)),NOT(ISNUMBER($G13)),$G13=0),0,$P13/$G13) -> 0.22401721 | S13: =IF(OR($B13="",NOT(ISNUMBER($F13))),"",SUMIFS(community_cores_FS!$P$5:$P$597,community_cores_FS!$B$5:$B$597,$B13,community_cores_FS!$F$5:$F$597,"<="&$F13)) -> 4.6437266 | T13: =IF(OR($B13="",$J13="",$M13=""),"Missing input",IF(OR($J13<0.02,$J13>1.2,$M13<0,$M13>60),"Check density or carbon units",IF($F13>REFERENCE_DEPTH_CM,"Below reference depth; included in sampled profile only",""))) -> Check density or carbon units
A14: FS-05 | B14: FS-05 | C14: 1 | D14: FS-05-3 | E14: 20 | F14: 30 | G14: =IF(AND(ISNUMBER($E14),ISNUMBER($F14)),$F14-$E14,"") -> 10 | I14: Whole sample / sample volume | J14: 1.6241369 | L14: 1.6 | M14: 0.9 | N14: =IF($M14<>"",$M14,IF($L14<>"",$L14*CARBON_FRACTION_OM,"")) -> 0.9 | O14: =IF(AND(ISNUMBER($E14),ISNUMBER($F14)),MAX(0,MIN($F14,REFERENCE_DEPTH_CM)-MIN($E14,REFERENCE_DEPTH_CM)),"") -> 10 | P14: =IF(AND(ISNUMBER($J14),ISNUMBER($N14),ISNUMBER($G14)),$J14*($N14/100)*$G14*10,"") -> 1.4617232 | Q14: =IF(AND(ISNUMBER($J14),ISNUMBER($N14),ISNUMBER($O14)),$J14*($N14/100)*$O14*10,"") -> 1.4617232 | R14: =IF(OR(NOT(ISNUMBER($P14)),NOT(ISNUMBER($G14)),$G14=0),0,$P14/$G14) -> 0.14617232 | S14: =IF(OR($B14="",NOT(ISNUMBER($F14))),"",SUMIFS(community_cores_FS!$P$5:$P$597,community_cores_FS!$B$5:$B$597,$B14,community_cores_FS!$F$5:$F$597,"<="&$F14)) -> 6.1054498 | T14: =IF(OR($B14="",$J14="",$M14=""),"Missing input",IF(OR($J14<0.02,$J14>1.2,$M14<0,$M14>60),"Check density or carbon units",IF($F14>REFERENCE_DEPTH_CM,"Below reference depth; included in sampled profile only",""))) -> Check density or carbon units
A15: FS-04 | B15: FS-04 | C15: 1 | D15: FS-04-1 | E15: 0 | F15: 10 | G15: =IF(AND(ISNUMBER($E15),ISNUMBER($F15)),$F15-$E15,"") -> 10 | I15: Whole sample / sample volume | J15: 1.974657 | L15: 5.5 | M15: 3.1 | N15: =IF($M15<>"",$M15,IF($L15<>"",$L15*CARBON_FRACTION_OM,"")) -> 3.1 | O15: =IF(AND(ISNUMBER($E15),ISNUMBER($F15)),MAX(0,MIN($F15,REFERENCE_DEPTH_CM)-MIN($E15,REFERENCE_DEPTH_CM)),"") -> 10 | P15: =IF(AND(ISNUMBER($J15),ISNUMBER($N15),ISNUMBER($G15)),$J15*($N15/100)*$G15*10,"") -> 6.1214368 | Q15: =IF(AND(ISNUMBER($J15),ISNUMBER($N15),ISNUMBER($O15)),$J15*($N15/100)*$O15*10,"") -> 6.1214368 | R15: =IF(OR(NOT(ISNUMBER($P15)),NOT(ISNUMBER($G15)),$G15=0),0,$P15/$G15) -> 0.61214368 | S15: =IF(OR($B15="",NOT(ISNUMBER($F15))),"",SUMIFS(community_cores_FS!$P$5:$P$597,community_cores_FS!$B$5:$B$597,$B15,community_cores_FS!$F$5:$F$597,"<="&$F15)) -> 6.1214368 | T15: =IF(OR($B15="",$J15="",$M15=""),"Missing input",IF(OR($J15<0.02,$J15>1.2,$M15<0,$M15>60),"Check density or carbon units",IF($F15>REFERENCE_DEPTH_CM,"Below reference depth; included in sampled profile only",""))) -> Check density or carbon units
A16: FS-04 | B16: FS-04 | C16: 1 | D16: FS-04-2 | E16: 10 | F16: 20 | G16: =IF(AND(ISNUMBER($E16),ISNUMBER($F16)),$F16-$E16,"") -> 10 | I16: Whole sample / sample volume | J16: 0.99685946 | L16: 3.2 | M16: 1.8 | N16: =IF($M16<>"",$M16,IF($L16<>"",$L16*CARBON_FRACTION_OM,"")) -> 1.8 | O16: =IF(AND(ISNUMBER($E16),ISNUMBER($F16)),MAX(0,MIN($F16,REFERENCE_DEPTH_CM)-MIN($E16,REFERENCE_DEPTH_CM)),"") -> 10 | P16: =IF(AND(ISNUMBER($J16),ISNUMBER($N16),ISNUMBER($G16)),$J16*($N16/100)*$G16*10,"") -> 1.794347 | Q16: =IF(AND(ISNUMBER($J16),ISNUMBER($N16),ISNUMBER($O16)),$J16*($N16/100)*$O16*10,"") -> 1.794347 | R16: =IF(OR(NOT(ISNUMBER($P16)),NOT(ISNUMBER($G16)),$G16=0),0,$P16/$G16) -> 0.1794347 | S16: =IF(OR($B16="",NOT(ISNUMBER($F16))),"",SUMIFS(community_cores_FS!$P$5:$P$597,community_cores_FS!$B$5:$B$597,$B16,community_cores_FS!$F$5:$F$597,"<="&$F16)) -> 7.9157838 | T16: =IF(OR($B16="",$J16="",$M16=""),"Missing input",IF(OR($J16<0.02,$J16>1.2,$M16<0,$M16>60),"Check density or carbon units",IF($F16>REFERENCE_DEPTH_CM,"Below reference depth; included in sampled profile only","")))
A17: FS-04 | B17: FS-04 | C17: 1 | D17: FS-04-3 | E17: 20 | F17: 30 | G17: =IF(AND(ISNUMBER($E17),ISNUMBER($F17)),$F17-$E17,"") -> 10 | I17: Whole sample / sample volume | J17: 1.0537351 | L17: 1.5 | M17: 0.8 | N17: =IF($M17<>"",$M17,IF($L17<>"",$L17*CARBON_FRACTION_OM,"")) -> 0.8 | O17: =IF(AND(ISNUMBER($E17),ISNUMBER($F17)),MAX(0,MIN($F17,REFERENCE_DEPTH_CM)-MIN($E17,REFERENCE_DEPTH_CM)),"") -> 10 | P17: =IF(AND(ISNUMBER($J17),ISNUMBER($N17),ISNUMBER($G17)),$J17*($N17/100)*$G17*10,"") -> 0.84298811 | Q17: =IF(AND(ISNUMBER($J17),ISNUMBER($N17),ISNUMBER($O17)),$J17*($N17/100)*$O17*10,"") -> 0.84298811 | R17: =IF(OR(NOT(ISNUMBER($P17)),NOT(ISNUMBER($G17)),$G17=0),0,$P17/$G17) -> 0.084298811 | S17: =IF(OR($B17="",NOT(ISNUMBER($F17))),"",SUMIFS(community_cores_FS!$P$5:$P$597,community_cores_FS!$B$5:$B$597,$B17,community_cores_FS!$F$5:$F$597,"<="&$F17)) -> 8.7587719 | T17: =IF(OR($B17="",$J17="",$M17=""),"Missing input",IF(OR($J17<0.02,$J17>1.2,$M17<0,$M17>60),"Check density or carbon units",IF($F17>REFERENCE_DEPTH_CM,"Below reference depth; included in sampled profile only","")))
A18: FS-03 | B18: FS-03 | C18: 1 | D18: FS-03-1 | E18: 0 | F18: 10 | G18: =IF(AND(ISNUMBER($E18),ISNUMBER($F18)),$F18-$E18,"") -> 10 | I18: Whole sample / sample volume | J18: 2.0632819 | L18: 1.8 | M18: 1 | N18: =IF($M18<>"",$M18,IF($L18<>"",$L18*CARBON_FRACTION_OM,"")) -> 1 | O18: =IF(AND(ISNUMBER($E18),ISNUMBER($F18)),MAX(0,MIN($F18,REFERENCE_DEPTH_CM)-MIN($E18,REFERENCE_DEPTH_CM)),"") -> 10 | P18: =IF(AND(ISNUMBER($J18),ISNUMBER($N18),ISNUMBER($G18)),$J18*($N18/100)*$G18*10,"") -> 2.0632819 | Q18: =IF(AND(ISNUMBER($J18),ISNUMBER($N18),ISNUMBER($O18)),$J18*($N18/100)*$O18*10,"") -> 2.0632819 | R18: =IF(OR(NOT(ISNUMBER($P18)),NOT(ISNUMBER($G18)),$G18=0),0,$P18/$G18) -> 0.20632819 | S18: =IF(OR($B18="",NOT(ISNUMBER($F18))),"",SUMIFS(community_cores_FS!$P$5:$P$597,community_cores_FS!$B$5:$B$597,$B18,community_cores_FS!$F$5:$F$597,"<="&$F18)) -> 2.0632819 | T18: =IF(OR($B18="",$J18="",$M18=""),"Missing input",IF(OR($J18<0.02,$J18>1.2,$M18<0,$M18>60),"Check density or carbon units",IF($F18>REFERENCE_DEPTH_CM,"Below reference depth; included in sampled profile only",""))) -> Check density or carbon units
... A22: FS-02 | B22: FS-02 | C22: 1 | D22: FS-02-2 | E22: 10 | F22: 20 | G22: =IF(AND(ISNUMBER($E22),ISNUMBER($F22)),$F22-$E22,"") -> 10 | I22: Whole sample / sample volume | J22: 1.497014 | L22: 3.5 | M22: 1.9 | N22: =IF($M22<>"",$M22,IF($L22<>"",$L22*CARBON_FRACTION_OM,"")) -> 1.9 | O22: =IF(AND(ISNUMBER($E22),ISNUMBER($F22)),MAX(0,MIN($F22,REFERENCE_DEPTH_CM)-MIN($E22,REFERENCE_DEPTH_CM)),"") -> 10 | P22: =IF(AND(ISNUMBER($J22),ISNUMBER($N22),ISNUMBER($G22)),$J22*($N22/100)*$G22*10,"") -> 2.8443267 | Q22: =IF(AND(ISNUMBER($J22),ISNUMBER($N22),ISNUMBER($O22)),$J22*($N22/100)*$O22*10,"") -> 2.8443267 | R22: =IF(OR(NOT(ISNUMBER($P22)),NOT(ISNUMBER($G22)),$G22=0),0,$P22/$G22) -> 0.28443267 | S22: =IF(OR($B22="",NOT(ISNUMBER($F22))),"",SUMIFS(community_cores_FS!$P$5:$P$597,community_cores_FS!$B$5:$B$597,$B22,community_cores_FS!$F$5:$F$597,"<="&$F22)) -> 6.7269888 | T22: =IF(OR($B22="",$J22="",$M22=""),"Missing input",IF(OR($J22<0.02,$J22>1.2,$M22<0,$M22>60),"Check density or carbon units",IF($F22>REFERENCE_DEPTH_CM,"Below reference depth; included in sampled profile only",""))) -> Check density or carbon units
A23: FS-02 | B23: FS-02 | C23: 1 | D23: FS-02-3 | E23: 20 | F23: 30 | G23: =IF(AND(ISNUMBER($E23),ISNUMBER($F23)),$F23-$E23,"") -> 10 | I23: Whole sample / sample volume | J23: 1.1030484 | L23: 2.7 | M23: 1.5 | N23: =IF($M23<>"",$M23,IF($L23<>"",$L23*CARBON_FRACTION_OM,"")) -> 1.5 | O23: =IF(AND(ISNUMBER($E23),ISNUMBER($F23)),MAX(0,MIN($F23,REFERENCE_DEPTH_CM)-MIN($E23,REFERENCE_DEPTH_CM)),"") -> 10 | P23: =IF(AND(ISNUMBER($J23),ISNUMBER($N23),ISNUMBER($G23)),$J23*($N23/100)*$G23*10,"") -> 1.6545726 | Q23: =IF(AND(ISNUMBER($J23),ISNUMBER($N23),ISNUMBER($O23)),$J23*($N23/100)*$O23*10,"") -> 1.6545726 | R23: =IF(OR(NOT(ISNUMBER($P23)),NOT(ISNUMBER($G23)),$G23=0),0,$P23/$G23) -> 0.16545726 | S23: =IF(OR($B23="",NOT(ISNUMBER($F23))),"",SUMIFS(community_cores_FS!$P$5:$P$597,community_cores_FS!$B$5:$B$597,$B23,community_cores_FS!$F$5:$F$597,"<="&$F23)) -> 8.3815614 | T23: =IF(OR($B23="",$J23="",$M23=""),"Missing input",IF(OR($J23<0.02,$J23>1.8,$M23<0,$M23>60),"Check density or carbon units",IF($F23>REFERENCE_DEPTH_CM,"Below reference depth; included in sampled profile only","")))
A24: FS-01 | B24: FS-01 | C24: 1 | D24: FS-01-1 | E24: 0 | F24: 10 | G24: =IF(AND(ISNUMBER($E24),ISNUMBER($F24)),$F24-$E24,"") -> 10 | I24: Whole sample / sample volume | J24: 1.7629047 | L24: 5.4 | M24: 3 | N24: =IF($M24<>"",$M24,IF($L24<>"",$L24*CARBON_FRACTION_OM,"")) -> 3 | O24: =IF(AND(ISNUMBER($E24),ISNUMBER($F24)),MAX(0,MIN($F24,REFERENCE_DEPTH_CM)-MIN($E24,REFERENCE_DEPTH_CM)),"") -> 10 | P24: =IF(AND(ISNUMBER($J24),ISNUMBER($N24),ISNUMBER($G24)),$J24*($N24/100)*$G24*10,"") -> 5.2887141 | Q24: =IF(AND(ISNUMBER($J24),ISNUMBER($N24),ISNUMBER($O24)),$J24*($N24/100)*$O24*10,"") -> 5.2887141 | R24: =IF(OR(NOT(ISNUMBER($P24)),NOT(ISNUMBER($G24)),$G24=0),0,$P24/$G24) -> 0.52887141 | S24: =IF(OR($B24="",NOT(ISNUMBER($F24))),"",SUMIFS(community_cores_FS!$P$5:$P$597,community_cores_FS!$B$5:$B$597,$B24,community_cores_FS!$F$5:$F$597,"<="&$F24)) -> 5.2887141 | T24: =IF(OR($B24="",$J24="",$M24=""),"Missing input",IF(OR($J24<0.02,$J24>1.8,$M24<0,$M24>60),"Check density or carbon units",IF($F24>REFERENCE_DEPTH_CM,"Below reference depth; included in sampled profile only","")))
A25: FS-01 | B25: FS-01 | C25: 1 | D25: FS-01-2 | E25: 10 | F25: 20 | G25: =IF(AND(ISNUMBER($E25),ISNUMBER($F25)),$F25-$E25,"") -> 10 | I25: Whole sample / sample volume | J25: 1.5938661 | L25: 7.3 | M25: 4.1 | N25: =IF($M25<>"",$M25,IF($L25<>"",$L25*CARBON_FRACTION_OM,"")) -> 4.1 | O25: =IF(AND(ISNUMBER($E25),ISNUMBER($F25)),MAX(0,MIN($F25,REFERENCE_DEPTH_CM)-MIN($E25,REFERENCE_DEPTH_CM)),"") -> 10 | P25: =IF(AND(ISNUMBER($J25),ISNUMBER($N25),ISNUMBER($G25)),$J25*($N25/100)*$G25*10,"") -> 6.5348508 | Q25: =IF(AND(ISNUMBER($J25),ISNUMBER($N25),ISNUMBER($O25)),$J25*($N25/100)*$O25*10,"") -> 6.5348508 | R25: =IF(OR(NOT(ISNUMBER($P25)),NOT(ISNUMBER($G25)),$G25=0),0,$P25/$G25) -> 0.65348508 | S25: =IF(OR($B25="",NOT(ISNUMBER($F25))),"",SUMIFS(community_cores_FS!$P$5:$P$597,community_cores_FS!$B$5:$B$597,$B25,community_cores_FS!$F$5:$F$597,"<="&$F25)) -> 11.823565 | T25: =IF(OR($B25="",$J25="",$M25=""),"Missing input",IF(OR($J25<0.02,$J25>1.8,$M25<0,$M25>60),"Check density or carbon units",IF($F25>REFERENCE_DEPTH_CM,"Below reference depth; included in sampled profile only","")))
A26: FS-01 | B26: FS-01 | C26: 1 | D26: FS-01-3 | E26: 20 | F26: 30 | G26: =IF(AND(ISNUMBER($E26),ISNUMBER($F26)),$F26-$E26,"") -> 10 | I26: Whole sample / sample volume | J26: 1.4349645 | L26: 3 | M26: 1.7 | N26: =IF($M26<>"",$M26,IF($L26<>"",$L26*CARBON_FRACTION_OM,"")) -> 1.7 | O26: =IF(AND(ISNUMBER($E26),ISNUMBER($F26)),MAX(0,MIN($F26,REFERENCE_DEPTH_CM)-MIN($E26,REFERENCE_DEPTH_CM)),"") -> 10 | P26: =IF(AND(ISNUMBER($J26),ISNUMBER($N26),ISNUMBER($G26)),$J26*($N26/100)*$G26*10,"") -> 2.4394396 | Q26: =IF(AND(ISNUMBER($J26),ISNUMBER($N26),ISNUMBER($O26)),$J26*($N26/100)*$O26*10,"") -> 2.4394396 | R26: =IF(OR(NOT(ISNUMBER($P26)),NOT(ISNUMBER($G26)),$G26=0),0,$P26/$G26) -> 0.24394396 | S26: =IF(OR($B26="",NOT(ISNUMBER($F26))),"",SUMIFS(community_cores_FS!$P$5:$P$597,community_cores_FS!$B$5:$B$597,$B26,community_cores_FS!$F$5:$F$597,"<="&$F26)) -> 14.263005 | T26: =IF(OR($B26="",$J26="",$M26=""),"Missing input",IF(OR($J26<0.02,$J26>1.8,$M26<0,$M26>60),"Check density or carbon units",IF($F26>REFERENCE_DEPTH_CM,"Below reference depth; included in sampled profile only","")))
G27: =IF(OR($E27="",$F27=""),"",$F27-$E27) | N27: =IF($M27<>"",$M27,IF($L27<>"",$L27*CARBON_FRACTION_OM,"")) | O27: =IF(OR($E27="",$F27=""),"",MAX(0,MIN($F27,REFERENCE_DEPTH_CM)-MIN($E27,REFERENCE_DEPTH_CM))) | P27: =IF(OR($J27="",$N27="",$G27=""),"",$J27*($N27/100)*$G27*10) | Q27: =IF(OR($J27="",$N27="",$O27=""),"",$J27*($N27/100)*$O27*10) | R27: =IF(OR(NOT(ISNUMBER($P27)),NOT(ISNUMBER($G27)),$G27=0),0,$P27/$G27) -> 0 | S27: =IF(OR($B27="",NOT(ISNUMBER($F27))),"",SUMIFS(community_cores_FS!$P$5:$P$597,community_cores_FS!$B$5:$B$597,$B27,community_cores_FS!$F$5:$F$597,"<="&$F27)) | T27: =IF(AND($A27="",$B27="",$E27=""),"",IF(AND($B27<>"",COUNTIF('2. Core Log'!$A$5:$A$124,$B27)=0),"Core ID not in Core Log. ","")&IF(AND($A27<>"",COUNTIF('1. Plot & Site Log'!$A$5:$A$64,$A27)=0),"Plot ID not in Plot & Site Log. ","")&IF(AND(ISNUMBER($E27),ISNUMBER($F27),$F27<=$E27),"Bottom depth is not below top depth. ","")&IF($I27="","Say which bulk-density basis the lab reported. ","")&IF(AND(ISNUMBER($J27),OR($J27<QC_BD_MIN,$J27>QC_BD_MAX)),"Bulk density outside "&QC_BD_MIN&"–"&QC_BD_MAX&" g/cm³ for peat. Above the top of that range usually means the mineral contact has been passed. ","")&IF(AND(ISNUMBER($N27),$N27>QC_CARBON_PCT_MAX),"Carbon above "&QC_CARBON_PCT_MAX&"% — check units; this may be organic matter rather than carbon. ","")&IF(AND($L27<>"",$M27<>""),"Both LOI and measured carbon given — the measured value is used. ","")&IF(AND($M27="",$L27<>"",OM_FACTOR_IS_LOCAL<>"Yes"),"Carbon derived from LOI using the default factor of "&CARBON_FRACTION_OM&", which has not been calibrated locally. See R1. Reference. ","")&IF(AND(ISNUMBER($O27),$O27=0,ISNUMBER($E27)),"Section lies entirely below the reference depth — it counts to the full-profile stock only. ",""))
G28: =IF(OR($E28="",$F28=""),"",$F28-$E28) | N28: =IF($M28<>"",$M28,IF($L28<>"",$L28*CARBON_FRACTION_OM,"")) | O28: =IF(OR($E28="",$F28=""),"",MAX(0,MIN($F28,REFERENCE_DEPTH_CM)-MIN($E28,REFERENCE_DEPTH_CM))) | P28: =IF(OR($J28="",$N28="",$G28=""),"",$J28*($N28/100)*$G28*10) | Q28: =IF(OR($J28="",$N28="",$O28=""),"",$J28*($N28/100)*$O28*10) | R28: =IF(OR(NOT(ISNUMBER($P28)),NOT(ISNUMBER($G28)),$G28=0),0,$P28/$G28) -> 0 | S28: =IF(OR($B28="",NOT(ISNUMBER($F28))),"",SUMIFS(community_cores_FS!$P$5:$P$597,community_cores_FS!$B$5:$B$597,$B28,community_cores_FS!$F$5:$F$597,"<="&$F28)) | T28: =IF(AND($A28="",$B28="",$E28=""),"",IF(AND($B28<>"",COUNTIF('2. Core Log'!$A$5:$A$124,$B28)=0),"Core ID not in Core Log. ","")&IF(AND($A28<>"",COUNTIF('1. Plot & Site Log'!$A$5:$A$64,$A28)=0),"Plot ID not in Plot & Site Log. ","")&IF(AND(ISNUMBER($E28),ISNUMBER($F28),$F28<=$E28),"Bottom depth is not below top depth. ","")&IF($I28="","Say which bulk-density basis the lab reported. ","")&IF(AND(ISNUMBER($J28),OR($J28<QC_BD_MIN,$J28>QC_BD_MAX)),"Bulk density outside "&QC_BD_MIN&"–"&QC_BD_MAX&" g/cm³ for peat. Above the top of that range usually means the mineral contact has been passed. ","")&IF(AND(ISNUMBER($N28),$N28>QC_CARBON_PCT_MAX),"Carbon above "&QC_CARBON_PCT_MAX&"% — check units; this may be organic matter rather than carbon. ","")&IF(AND($L28<>"",$M28<>""),"Both LOI and measured carbon given — the measured value is used. ","")&IF(AND($M28="",$L28<>"",OM_FACTOR_IS_LOCAL<>"Yes"),"Carbon derived from LOI using the default factor of "&CARBON_FRACTION_OM&", which has not been calibrated locally. See R1. Reference. ","")&IF(AND(ISNUMBER($O28),$O28=0,ISNUMBER($E28)),"Section lies entirely below the reference depth — it counts to the full-profile stock only. ",""))
